<?xml version="1.0"?>
<robot xmlns:xacro="http://www.ros.org/wiki/xacro" name="diffbot">

  <xacro:property name="wheel_radius" value="0.075"/>
  <xacro:property name="wheel_separation" value="0.32"/>

  <!-- base_footprint 用于2D导航常见基座帧 -->
  <link name="base_footprint"/>
  <joint name="base_footprint_joint" type="fixed">
    <parent link="base_footprint"/>
    <child link="base_link"/>
    <origin xyz="0 0 0" rpy="0 0 0"/>
  </joint>

  <!-- Base Link (车体) -->
  <link name="base_link">
    <inertial>
      <origin xyz="0 0 0.08" rpy="0 0 0"/>
      <mass value="8.0"/>
      <inertia ixx="0.12" ixy="0" ixz="0" iyy="0.20" iyz="0" izz="0.25"/>
    </inertial>
    <visual>
      <origin xyz="0 0 0.08" rpy="0 0 0"/>
      <geometry>
        <box size="0.40 0.25 0.10"/>
      </geometry>
      <material name="blue">
        <color rgba="0.0 0.0 0.8 1.0"/>
      </material>
    </visual>
    <collision>
      <origin xyz="0 0 0.08" rpy="0 0 0"/>
      <geometry>
        <box size="0.40 0.25 0.10"/>
      </geometry>
    </collision>
  </link>

  <!-- Left Wheel (左轮) -->
  <link name="left_wheel_link">
    <inertial>
      <origin xyz="0 0 0" rpy="0 0 0"/>
      <mass value="0.6"/>
      <inertia ixx="0.001" ixy="0" ixz="0" iyy="0.001" iyz="0" izz="0.001"/>
    </inertial>
    <visual>
      <origin xyz="0 0 0" rpy="${pi/2} 0 0"/>
      <geometry>
        <cylinder radius="${wheel_radius}" length="0.04"/>
      </geometry>
      <material name="black">
        <color rgba="0.1 0.1 0.1 1.0"/>
      </material>
    </visual>
    <collision>
      <origin xyz="0 0 0" rpy="${pi/2} 0 0"/>
      <geometry>
        <cylinder radius="${wheel_radius}" length="0.04"/>
      </geometry>
    </collision>
  </link>

  <!-- Right Wheel (右轮) -->
  <link name="right_wheel_link">
    <inertial>
      <origin xyz="0 0 0" rpy="0 0 0"/>
      <mass value="0.6"/>
      <inertia ixx="0.001" ixy="0" ixz="0" iyy="0.001" iyz="0" izz="0.001"/>
    </inertial>
    <visual>
      <origin xyz="0 0 0" rpy="${pi/2} 0 0"/>
      <geometry>
        <cylinder radius="${wheel_radius}" length="0.04"/>
      </geometry>
      <material name="black">
        <color rgba="0.1 0.1 0.1 1.0"/>
      </material>
    </visual>
    <collision>
      <origin xyz="0 0 0" rpy="${pi/2} 0 0"/>
      <geometry>
        <cylinder radius="${wheel_radius}" length="0.04"/>
      </geometry>
    </collision>
  </link>

  <!-- Joints (关节连接) -->
  <joint name="left_wheel_joint" type="continuous">
    <parent link="base_link"/>
    <child link="left_wheel_link"/>
    <origin xyz="0 ${wheel_separation/2} ${wheel_radius}" rpy="0 0 0"/>
    <axis xyz="0 1 0"/>
  </joint>

  <joint name="right_wheel_joint" type="continuous">
    <parent link="base_link"/>
    <child link="right_wheel_link"/>
    <origin xyz="0 -${wheel_separation/2} ${wheel_radius}" rpy="0 0 0"/>
    <axis xyz="0 1 0"/>
  </joint>

  <link name="front_caster_link">
    <inertial>
      <origin xyz="0 0 0" rpy="0 0 0"/>
      <mass value="0.2"/>
      <inertia ixx="0.0003" ixy="0" ixz="0" iyy="0.0003" iyz="0" izz="0.0003"/>
    </inertial>
    <visual>
      <geometry>
        <sphere radius="0.03"/>
      </geometry>
      <material name="black"/>
    </visual>
    <collision>
      <geometry>
        <sphere radius="0.03"/>
      </geometry>
    </collision>
  </link>

  <joint name="front_caster_joint" type="fixed">
    <parent link="base_link"/>
    <child link="front_caster_link"/>
    <origin xyz="0.17 0 0.03" rpy="0 0 0"/>
  </joint>

  <link name="rear_caster_link">
    <inertial>
      <origin xyz="0 0 0" rpy="0 0 0"/>
      <mass value="0.2"/>
      <inertia ixx="0.0003" ixy="0" ixz="0" iyy="0.0003" iyz="0" izz="0.0003"/>
    </inertial>
    <visual>
      <geometry>
        <sphere radius="0.03"/>
      </geometry>
      <material name="black"/>
    </visual>
    <collision>
      <geometry>
        <sphere radius="0.03"/>
      </geometry>
    </collision>
  </link>

  <joint name="rear_caster_joint" type="fixed">
    <parent link="base_link"/>
    <child link="rear_caster_link"/>
    <origin xyz="-0.17 0 0.03" rpy="0 0 0"/>
  </joint>

  <!-- Gazebo 材质与摩擦力 -->
  <gazebo reference="base_link">
    <material>Gazebo/Blue</material>
  </gazebo>
  <gazebo reference="left_wheel_link">
    <material>Gazebo/Black</material>
    <mu1>0.7</mu1>
    <mu2>0.7</mu2>
    <slip1>0.02</slip1>
    <slip2>0.02</slip2>
  </gazebo>
  <gazebo reference="right_wheel_link">
    <material>Gazebo/Black</material>
    <mu1>0.7</mu1>
    <mu2>0.7</mu2>
    <slip1>0.02</slip1>
    <slip2>0.02</slip2>
  </gazebo>
  <gazebo reference="front_caster_link">
    <material>Gazebo/Black</material>
    <mu1>0.02</mu1>
    <mu2>0.02</mu2>
  </gazebo>
  <gazebo reference="rear_caster_link">
    <material>Gazebo/Black</material>
    <mu1>0.02</mu1>
    <mu2>0.02</mu2>
  </gazebo>

   <gazebo>
    <plugin name="joint_state_publisher" filename="libgazebo_ros_joint_state_publisher.so">
      <update_rate>100</update_rate>
      <joint_name>left_wheel_joint</joint_name>
      <joint_name>right_wheel_joint</joint_name>
    </plugin>
    <plugin name="diff_drive" filename="libgazebo_ros_diff_drive.so">
      <ros>
        <remapping>/tf:=tf</remapping>
        <remapping>/tf_static:=tf_static</remapping>
        <remapping>cmd_vel:=cmd_vel</remapping>
        <remapping>odom:=odom</remapping>
      </ros>

      <update_rate>100</update_rate>

      <!-- wheels -->
      <left_joint>left_wheel_joint</left_joint>
      <right_joint>right_wheel_joint</right_joint>

      <!-- kinematics -->
      <wheel_separation>0.32</wheel_separation>
      <wheel_diameter>0.15</wheel_diameter>

      <!-- limits -->
      <max_wheel_torque>40</max_wheel_torque>
      <max_wheel_acceleration>12.0</max_wheel_acceleration>

      <!-- output -->
      <publish_odom>true</publish_odom>
      <publish_odom_tf>true</publish_odom_tf>
      <publish_wheel_tf>false</publish_wheel_tf>

      <odometry_frame>odom</odometry_frame>
      <robot_base_frame>base_link</robot_base_frame>
    </plugin>
  </gazebo>
  <!-- 2D LiDAR (雷达) -->
  <link name="laser">
    <visual>
      <geometry>
        <cylinder radius="0.05" length="0.04"/>
      </geometry>
      <material name="red">
        <color rgba="1 0 0 1"/>
      </material>
    </visual>
    <collision>
      <geometry>
        <cylinder radius="0.05" length="0.04"/>
      </geometry>
    </collision>
    <inertial>
      <origin xyz="0 0 0" rpy="0 0 0"/>
      <mass value="0.1"/>
      <inertia ixx="0.0001" ixy="0" ixz="0" iyy="0.0001" iyz="0" izz="0.0001"/>
    </inertial>
  </link>

  <joint name="laser_joint" type="fixed">
    <parent link="base_link"/>
    <child link="laser"/>
    <origin xyz="0.22 0 0.16" rpy="0 0 0"/>
  </joint>

  <gazebo reference="laser">
    <material>Gazebo/Red</material>
    <sensor name="laser" type="ray">
      <pose> 0 0 0 0 0 0 </pose>
      <visualize>true</visualize>
      <update_rate>10</update_rate>
      <ray>
        <scan>
          <horizontal>
            <samples>360</samples>
            <min_angle>-3.14</min_angle>
            <max_angle>3.14</max_angle>
          </horizontal>
        </scan>
        <range>
          <min>0.1</min>
          <max>12.0</max>
        </range>
      </ray>
      <plugin name="laser_controller" filename="libgazebo_ros_ray_sensor.so">
        <ros>
          <argument>~/out:=scan</argument>
        </ros>
        <output_type>sensor_msgs/LaserScan</output_type>
        <frame_name>laser</frame_name>
      </plugin>
    </sensor>
  </gazebo>

  <!-- Camera (相机) -->
  <link name="camera_link">
    <visual>
      <geometry>
        <box size="0.05 0.05 0.05"/>
      </geometry>
      <material name="black"/>
    </visual>
  </link>

  <joint name="camera_joint" type="fixed">
    <parent link="base_link"/>
    <child link="camera_link"/>
    <origin xyz="0.2 0 0.08" rpy="0 0 0"/>
  </joint>

  <gazebo reference="camera_link">
    <material>Gazebo/Black</material>
    <sensor name="camera" type="camera">
      <pose> 0 0 0 0 0 0 </pose>
      <visualize>true</visualize>
      <update_rate>10</update_rate>
      <camera>
        <horizontal_fov>1.089</horizontal_fov>
        <image>
          <format>R8G8B8</format>
          <width>640</width>
          <height>480</height>
        </image>
        <clip>
          <near>0.05</near>
          <far>8.0</far>
        </clip>
      </camera>
      <plugin name="camera_controller" filename="libgazebo_ros_camera.so">
        <frame_name>camera_link</frame_name>
      </plugin>
    </sensor>
  </gazebo>
</robot>
